Workbook
Name Slicer_Year: #N/A

Sheet Financial Statement 
A1: Balance sheet check >> | B1: =IF(ABS(B93)<=1,"ok","Error") -> ok | C1: =IF(ABS(C93)<=1,"ok","Error") -> ok | D1: =IF(ABS(D93)<=1,"ok","Error") -> ok | E1: =IF(ABS(E93)<=1,"ok","Error") -> ok | F1: =IF(ABS(F93)<=1,"ok","Error") -> ok | G1: =IF(ABS(G93)<=1,"ok","Error") -> ok | H1: =IF(ABS(H93)<=1,"ok","Error") -> ok | I1: =IF(ABS(I93)<=1,"ok","Error") -> ok | ... P1: =IF(ABS(P93)<=1,"ok","Error") -> ok
A2: All Values are in MI | B2: 2016 | C2: 2017 | D2: 2018 | E2: 2019 | F2: 2020 | G2: 2021 | H2: 2022 | I2: 2023 | J2: 2024 | K2: 2025 | L2: 2026 | M2: 2027 | N2: 2028 | O2: 2029 | P2: 2030 | Q2: 2031 | R2: 2032 | S2: 2033 | T2: 2034 | U2: 2035 | V2: 2036 | W2: Terminal Value
A4: Revenue
A5: Gross Revenue From Operation | B5: 570615 | C5: 680850 | D5: 798094 | E5: 860685 | F5: 756600 | G5: 703720 | H5: 883298 | I5: 1184099 | J5: 1418582 | K5: =K101*K125/10^6 -> 1750571.8 | L5: =L101*L125/10^6 -> 2051120.2 | M5: =M101*M125/10^6 -> 2404139.8 | N5: =N101*N125/10^6 -> 2818896 | O5: =O101*O125/10^6 -> 3306302.3 | P5: =P101*P125/10^6 -> 3879215.2
A6: Other Income | B6: 15505 | C6: 22896 | D6: 20458 | E6: 25616 | F6: 33344 | G6: 29363 | H6: 17447 | I6: 22647 | J6: 40935 | K6: 20000 | L6: =K6 -> 20000 | M6: =L6 -> 20000 | N6: =M6 -> 20000 | O6: =N6 -> 20000 | P6: =O6 -> 20000
A8: Total Revenue | B8: =B5+B6 -> 586120 | C8: =C5+C6 -> 703746 | D8: =D5+D6 -> 818552 | E8: =E5+E6 -> 886301 | F8: =F5+F6 -> 789944 | G8: =G5+G6 -> 733083 | H8: =H5+H6 -> 900745 | I8: =I5+I6 -> 1206746 | ... P8: =P5+P6 -> 3899215.2
A10: Cost
A11: Raw Materials | B11: 362007 | C11: 426279 | D11: 449432 | E11: 450257 | F11: 346348 | G11: 332964 | H11: 397396 | I11: 733522 | J11: 789153 | K11: =K5*K130 -> 1050343.1 | L11: =L5*L130 -> 1230672.1 | M11: =M5*M130 -> 1442483.9 | N11: =N5*N130 -> 1691337.6 | O11: =O5*O130 -> 1983781.4 | P11: =P5*P130 -> 2327529.1
A12: Purchases | B12: 31715 | C12: 44936 | D12: 100021 | E12: 143209 | F12: 187672 | G12: 172541 | H12: 263975 | I12: 127147 | J12: 212042 | K12: =K5*K131 -> 140045.75 | L12: =L5*L131 -> 164089.61 | M12: =M5*M131 -> 192331.19 | N12: =N5*N131 -> 225511.68 | O12: =O5*O131 -> 264504.18 | P12: =P5*P131 -> 310337.21
A13: Changes in Stock in trade | B13: 63 | C13: -3793 | D13: 408 | E13: 2116 | F13: -2378 | G13: 2736 | H13: -931 | I13: -5805 | J13: -3786 | K13: =K5*K132 -> -4672.0351 | L13: =L5*L132 -> -5474.1572 | M13: =M5*M132 -> -6416.3181 | N13: =N5*N132 -> -7523.2452 | O13: =O5*O132 -> -8824.0654 | P13: =P5*P132 -> -10353.091
A14: Employee Cost | B14: 20602 | C14: 23603 | D14: 28634 | E14: 32850 | F14: 34162 | G14: 34316 | H14: 40514 | I14: 53085 | J14: 63016 | K14: =K5*K133 -> 70022.873 | L14: =L5*L133 -> 82044.807 | M14: =M5*M133 -> 96165.593 | N14: =N5*N133 -> 112755.84 | O14: =O5*O133 -> 132252.09 | P14: =P5*P133 -> 155168.61
A15: Others expenses | B15: 81147 | C15: 87280 | D15: 99956 | E15: 123442 | F15: 118896 | G15: 108375 | H15: 126727 | I15: 146771 | J15: 175501 | K15: =K5*K134 -> 217070.91 | L15: =L5*L134 -> 254338.9 | M15: =M5*M134 -> 298113.34 | N15: =N5*N134 -> 349543.1 | O15: =O5*O134 -> 409981.48 | P15: =P5*P134 -> 481022.68
A16: Vehicles or Dies for Own Usage | B16: -602 | C16: -1036 | D16: -991 | E16: -1221 | F16: -1217 | G16: -728 | H16: -1445 | I16: -1565 | J16: -2607 | K16: =K5*K135 -> -3217.1145 | L16: =L5*L135 -> -3769.4474 | M16: =M5*M135 -> -4418.2095 | N16: =N5*N135 -> -5180.428 | O16: =O5*O135 -> -6076.1592 | P16: =P5*P135 -> -7129.0302
A18: Total Costs | B18: =SUM(B11:B16) -> 494932 | C18: =SUM(C11:C16) -> 577269 | D18: =SUM(D11:D16) -> 677460 | E18: =SUM(E11:E16) -> 750653 | F18: =SUM(F11:F16) -> 683483 | G18: =SUM(G11:G16) -> 650204 | H18: =SUM(H11:H16) -> 826236 | I18: =SUM(I11:I16) -> 1053155 | ... P18: =SUM(P11:P16) -> 3256575.5
A20: Operating Profit | B20: =B8-B18 -> 91188 | C20: =C8-C18 -> 126477 | D20: =D8-D18 -> 141092 | E20: =E8-E18 -> 135648 | F20: =F8-F18 -> 106461 | G20: =G8-G18 -> 82879 | H20: =H8-H18 -> 74509 | I20: =I8-I18 -> 153591 | ... P20: =P8-P18 -> 642639.69
A22: Depriciation & Amortization | B22: 28670 | C22: 26039 | D22: 27598 | E22: 30208 | F22: 35284 | G22: 30341 | H22: 27890 | I22: 48460 | J22: 52558 | K22: =K191 -> 60235.688 | L22: =L191 -> 67322.24 | M22: =M191 -> 74408.791 | N22: =N191 -> 81495.343 | O22: =O191 -> 88581.894 | P22: =P191 -> 95668.446
A24: EBIT | B24: =B20-B22 -> 62518 | C24: =C20-C22 -> 100438 | D24: =D20-D22 -> 113494 | E24: =E20-E22 -> 105440 | F24: =F20-F22 -> 71177 | G24: =G20-G22 -> 52538 | H24: =H20-H22 -> 46619 | I24: =I20-I22 -> 105131 | ... P24: =P20-P22 -> 546971.24
A26: Interest | B26: 937 | C26: 894 | D26: 3458 | E26: 759 | F26: 1342 | G26: 1018 | H26: 1266 | I26: 2523 | J26: 1936 | K26: =J26 -> 1936 | L26: =K26 -> 1936 | M26: =L26 -> 1936 | N26: =M26 -> 1936 | O26: =N26 -> 1936 | P26: =O26 -> 1936
A28: Profit Before Exceptional Items and taxes | B28: =B24-B26 -> 61581 | C28: =C24-C26 -> 99544 | D28: =D24-D26 -> 110036 | E28: =E24-E26 -> 104681 | F28: =F24-F26 -> 69835 | G28: =G24-G26 -> 51520 | H28: =H24-H26 -> 45353 | I28: =I24-I26 -> 102608 | ... P28: =P24-P26 -> 545035.24
A29: Others / Exceptional Items
A30: Profit Before Taxes | B30: =SUM(B28:B29) -> 61581 | C30: =SUM(C28:C29) -> 99544 | D30: =SUM(D28:D29) -> 110036 | E30: =SUM(E28:E29) -> 104681 | F30: =SUM(F28:F29) -> 69835 | G30: =SUM(G28:G29) -> 51520 | H30: =SUM(H28:H29) -> 45353 | I30: =SUM(I28:I29) -> 102608 | ... P30: =SUM(P28:P29) -> 545035.24
A32: Taxes | B32: 19987 | C32: 26162 | D32: 32862 | E32: 29732 | F32: 14252 | G32: 9319 | H32: 8177 | I32: 21745 | J32: 39363 | K32: =K30*K33 -> 59701.667 | L32: =L30*L33 -> 69990.028 | M32: =M30*M33 -> 82383.887 | N32: =N30*N33 -> 97255.027 | O32: =O30*O33 -> 115041.37 | P32: =P30*P33 -> 136258.81
K33: 0.25 | L33: 0.25 | M33: 0.25 | N33: 0.25 | O33: 0.25 | P33: 0.25
A34: Profit Before Minoriy Interest and Share in Associates | B34: =B30-B32 -> 41594 | C34: =C30-C32 -> 73382 | D34: =D30-D32 -> 77174 | E34: =E30-E32 -> 74949 | F34: =F30-F32 -> 55583 | G34: =G30-G32 -> 42201 | H34: =H30-H32 -> 37176 | I34: =I30-I32 -> 80863 | ... P34: =P30-P32 -> 408776.43
A35: Shares in Associates + JV | B35: 679 | C35: 2216 | D35: 3311 | E35: 1557 | F35: 1184 | G35: 1690 | H35: 1619 | I35: 1774 | J35: 2541 | K35: =J35 -> 2541 | L35: =K35 -> 2541 | M35: =L35 -> 2541 | N35: =M35 -> 2541 | O35: =N35 -> 2541 | P35: =O35 -> 2541
A37: Profit For the Year | B37: =B34+B35 -> 42273 | C37: =C34+C35 -> 75598 | D37: =D34+D35 -> 80485 | E37: =E34+E35 -> 76506 | F37: =F34+F35 -> 56767 | G37: =G34+G35 -> 43891 | H37: =H34+H35 -> 38795 | I37: =I34+I35 -> 82637 | ... P37: =P34+P35 -> 411317.43
A39: Source of Funds
A41: Shareholders Funds | B41: =SUM(B42:B47) -> 306304 | C41: =SUM(C42:C47) -> 370905 | D41: =SUM(D42:D47) -> 425755 | E41: =SUM(E42:E47) -> 471097 | F41: 494322 | G41: =SUM(G42:G47) -> 525006 | H41: =SUM(H42:H47) -> 553335 | I41: =SUM(I42:I47) -> 746002 | J41: =SUM(J42:J47) -> 856360 | K41: =SUM(K42:K47) -> 1038006 | L41: =SUM(L42:L47) -> 1250517.1 | M41: =SUM(M42:M47) -> 1500209.7 | N41: =SUM(N42:N47) -> 1794515.8 | ... P41: =SUM(P42:P47) -> 2553498.4
A42: Share Capital | B42: 1510 | C42: 1510 | D42: 1510 | E42: 1510 | F42: 1510 | G42: 1510 | H42: 1510 | I42: 1572 | J42: 1572 | K42: =J42 -> 1572 | L42: =K42 -> 1572 | M42: =L42 -> 1572 | N42: =M42 -> 1572 | O42: =N42 -> 1572 | P42: =O42 -> 1572
A43: Reserves & Surplus | B43: 304650 | C43: 369241 | D43: 424084 | E43: 469411 | F43: 492620 | G43: 523496 | H43: 551825 | I43: 744430 | J43: 854788 | K43: =J43+K37 -> 1036434 | L43: =K43+L37 -> 1248945.1 | M43: =L43+M37 -> 1498637.7 | N43: =M43+N37 -> 1792943.8 | O43: =N43+O37 -> 2140608.9 | P43: =O43+P37 -> 2551926.4
A44: Money Received Against Warrants | B44: 0 | C44: 0 | D44: 0 | E44: 0 | H44: 0 | I44: 0 | J44: 0 | K44: =J44 -> 0 | L44: =K44 -> 0 | M44: =L44 -> 0 | N44: =M44 -> 0 | O44: =N44 -> 0 | P44: =O44 -> 0
A46: Minority Interest | B46: 144 | C46: 154 | D46: 161 | E46: 176 | F46: 192 | G46: 0 | H46: 0 | I46: 0 | J46: 0 | K46: =J46 -> 0 | L46: =K46 -> 0 | M46: =L46 -> 0 | N46: =M46 -> 0 | O46: =N46 -> 0 | P46: =O46 -> 0
A47: Share Application Money Pending Allotment | B47: 0 | C47: 0 | D47: 0 | E47: 0 | F47: 0 | G47: 0 | H47: 0 | I47: 0 | J47: 0 | K47: =J47 -> 0 | L47: =K47 -> 0 | M47: =L47 -> 0 | N47: =M47 -> 0 | O47: =N47 -> 0 | P47: =O47 -> 0
A49: Long Term Liabilities | B49: =SUM(B50:B53) -> 10510 | C49: =SUM(C50:C53) -> 16332 | D49: =SUM(D50:D53) -> 22244 | E49: =SUM(E50:E53) -> 26985 | F49: =SUM(F50:F53) -> 28901 | G49: =SUM(G50:G53) -> 26616 | H49: =SUM(H50:H53) -> 22985 | I49: =SUM(I50:I53) -> 30185 | ... P49: =SUM(P50:P53) -> 37630
A50: Loans | B50: 0 | C50: 0 | D50: 100 | E50: 80 | F50: 652 | G50: 420 | H50: 329 | I50: 250 | J50: 677 | K50: =J50 -> 677 | L50: =K50 -> 677 | M50: =L50 -> 677 | N50: =M50 -> 677 | O50: =N50 -> 677 | P50: =O50 -> 677
A51: Other Long term Liabilities | B51: 8075 | C51: 11055 | D51: 15859 | E51: 20371 | F51: 21158 | G51: 21295 | H51: 21812 | I51: 25850 | J51: 31617 | K51: =J51 -> 31617 | L51: =K51 -> 31617 | M51: =L51 -> 31617 | N51: =M51 -> 31617 | O51: =N51 -> 31617 | P51: =O51 -> 31617
A52: Long term Provision | B52: 148 | C52: 219 | D52: 265 | E52: 395 | F52: 516 | G52: 447 | H52: 844 | I52: 875 | J52: 1448 | K52: =J52 -> 1448 | L52: =K52 -> 1448 | M52: =L52 -> 1448 | N52: =M52 -> 1448 | O52: =N52 -> 1448 | P52: =O52 -> 1448
A53: Deffered Taxes Liabilities | B53: 2287 | C53: 5058 | D53: 6020 | E53: 6139 | F53: 6575 | G53: 4454 | H53: 0 | I53: 3210 | J53: 3888 | K53: =J53 -> 3888 | L53: =K53 -> 3888 | M53: =L53 -> 3888 | N53: =M53 -> 3888 | O53: =N53 -> 3888 | P53: =O53 -> 3888
A55: Current Liabilties | B55: =SUM(B56:B62) -> 110441 | C55: =SUM(C56:C62) -> 132368 | D55: =SUM(D56:D62) -> 154485 | E55: =SUM(E56:E62) -> 141605 | F55: =SUM(F56:F62) -> 113054 | G55: =SUM(G56:G62) -> 162139 | H55: =SUM(H56:H62) -> 170235 | I55: =SUM(I56:I62) -> 227667 | ... P55: =SUM(P56:P62) -> 735034.85
A56: Tax Liabilities | B56: 7956 | C56: 8036 | D56: 8541 | E56: 6729 | F56: 6962 | G56: 8547 | H56: 11113 | I56: 11584 | J56: 12030 | K56: =K149 -> 14845.373 | L56: =L149 -> 17394.113 | M56: =M149 -> 20387.825 | N56: =N149 -> 23905.082 | O56: =O149 -> 28038.433 | P56: =P149 -> 32896.906
...

Sheet Dashboard
B2: Maruti Suzuki- Financial Ratio Dashboard (All Figures in ₹)
N40: Year | P40: Return on Equity | S40: Return on Asset
N42: 2025 | P42: ='Ratio''s'!G4 -> 0.17254717 | S42: ='Ratio''s'!H4 -> 0.12726537
N43: 2026 | P43: ='Ratio''s'!G5 -> 0.16790661 | S43: ='Ratio''s'!H5 -> 0.12522116
N44: 2027 | P44: ='Ratio''s'!G6 -> 0.16258708 | S44: ='Ratio''s'!H6 -> 0.12330163
N45: 2028 | P45: ='Ratio''s'!G7 -> 0.16110876 | S45: ='Ratio''s'!H6 -> 0.12330163
N46: 2029 | P46: ='Ratio''s'!G8 -> 0.16008486 | S46: ='Ratio''s'!H7 -> 0.12298234
N47: 2030 | P47: ='Ratio''s'!G9 -> 0.16343396 | S47: ='Ratio''s'!H8 -> 0.12289729

Sheet KPI'S
B3: Sum of Total Revenue | E3: Net profit margin | H3: Debt to EBITDA
B4: 13906105 | E4: 0.10317344 | H4: 0.12107814
B13: EBITDA Margin | E13: Return on Equity
B14: 0.16654348 | E14: 0.16343396 | H14: Interest Coverage Ratio
H15: 1.9862269

Sheet Free Cash Flow 
B3: Row Labels | C3: Sum of Cash flow
B4: 2025 | C4: 205349.35
B5: 2026 | C5: 193140.71
B6: 2028 | C6: 283122.04
B7: 2029 | C7: 341688.58
B8: 2030 | C8: 411469.95
B9: Grand Total | C9: 1434770.6

Sheet Revenue & EBITDA
B3: Row Labels | C3: Sum of Total Revenue | D3: EBITDA Margin
B4: 2025 | C4: 1770571.8 | D4: 0.16998935
B5: 2026 | C5: 2071120.2 | D5: 0.16861327
B6: 2028 | C6: 2838896 | D6: 0.16642084
B7: 2029 | C7: 3326302.3 | D7: 0.16555422
B8: 2030 | C8: 3899215.2 | D8: 0.16481257
B9: Grand Total | C9: 13906105 | D9: 0.16654348

Sheet Ratio's
B3: Row Labels | C3: Cash Ratio | D3: Current Ratio | F3: Row Labels | G3: Return on Equity | H3: Return on Assets
B4: 2025 | C4: 6.1908365 | D4: 1.3260297 | F4: 2025 | G4: 0.17254717 | H4: 0.12726537
B5: 2026 | C5: 4.9695683 | D5: 1.7197828 | F5: 2026 | G5: 0.16790661 | H5: 0.12522116
B6: 2028 | C6: 5.3006675 | D6: 2.3890247 | F6: 2028 | G6: 0.16258708 | H6: 0.12330163
B7: 2029 | C7: 5.4541094 | D7: 2.6739022 | F7: 2029 | G7: 0.16110876 | H7: 0.12298234
B8: 2030 | C8: 5.5979651 | D8: 2.9306143 | F8: 2030 | G8: 0.16008486 | H8: 0.12289729
B9: Grand Total | C9: 5.4846287 | D9: 2.3752112 | F9: Grand Total | G9: 0.16343396 | H9: 0.12386764
B16: Year | C16: EBITDA Margin | D16: Net profit margin | E16: Return on Equity | F16: Debt to EBITDA | G16: Interest Coverage Ratio | H16: Current Ratio
B17: 2025 | C17: 0.16998935 | D17: 0.10115659 | E17: 0.17254717 | F17: 0.12270945 | G17: 1.2435055 | H17: 1.3260297
B18: 2026 | C18: 0.16861327 | D18: 0.10137996 | E18: 0.16790661 | F18: 0.122066 | G18: 1.456075 | H18: 1.7197828
B19: 2028 | C19: 0.16642084 | D19: 0.10277413 | E19: 0.16258708 | F19: 0.12101884 | G19: 2.0194014 | H19: 2.3890247
B20: 2029 | C20: 0.16555422 | D20: 0.10375609 | E20: 0.16110876 | F20: 0.12059727 | G20: 2.3868878 | H20: 2.6739022
B21: 2030 | C21: 0.16481257 | D21: 0.10483557 | E21: 0.16008486 | F21: 0.12023298 | G21: 2.8252647 | H21: 2.9306143
B22: Grand Total | C22: 0.16654348 | D22: 0.10317344 | E22: 0.16343396 | F22: 0.12107814 | G22: 1.9862269 | H22: 2.3752112

Sheet ROE Trend
B3: Row Labels | C3: Return on Equity
B4: 2025 | C4: 0.17254717
B5: 2026 | C5: 0.16790661
B6: 2028 | C6: 0.16258708
B7: 2029 | C7: 0.16110876
B8: 2030 | C8: 0.16008486
B9: Grand Total | C9: 0.16343396

Sheet Debt vs EBITDA
B3: Row Labels | C3: Sum of Total Liabilites | D3: Sum of Operating Profit
B4: 2025 | C4: 369328.87 | D4: 300978.35
B5: 2026 | C5: 426276.86 | D5: 349218.35
B6: 2028 | C6: 571755.26 | D6: 472451.45
B7: 2029 | C7: 664109.14 | D7: 550683.38
B8: 2030 | C8: 772664.85 | D8: 642639.69
B9: Grand Total | C9: 2804135 | D9: 2315971.2

Sheet Revenue By Category
B3: Row Labels | C3: Sum of Total Revenue
B4: 2025 | C4: 1770571.8
B5: 2026 | C5: 2071120.2
B6: 2028 | C6: 2838896
B7: 2029 | C7: 3326302.3
B8: 2030 | C8: 3899215.2
B9: Grand Total | C9: 13906105

Sheet Sheet2
A1: Year | B1: Total Revenue | C1: Total Cost | D1: Operating Profit | E1: Depricition & Amortization | F1: EBIT | G1: Interest | H1: Profit Before Exceptional item | I1: Tax | J1: Net Profit | K1: Total Equity | L1: Total Current Liabilities | M1: Total Long term liabilities | N1: Total Liabilites | O1: Total Liability & Equity | P1: Total Current Asset | Q1: Total Long term Assets | R1: Total Asset | S1: Check | T1: Capacity | U1: New Capacity | V1: Working capital | W1: Capex Schedule | X1: Assets per Car | Y1: Cash flow
A2: 2025 | B2: ='Financial Statement '!K8 -> 1770571.8 | C2: ='Financial Statement '!K18 -> 1469593.5 | D2: =B2-C2 -> 300978.35 | E2: ='Financial Statement '!K22 -> 60235.688 | F2: =D2-E2 -> 240742.67 | G2: ='Financial Statement '!K26 -> 1936 | H2: =F2-G2 -> 238806.67 | I2: ='Financial Statement '!K32 -> 59701.667 | J2: =H2-I2 -> 179105 | K2: ='Financial Statement '!K41 -> 1038006 | L2: ='Financial Statement '!K55 -> 331698.87 | M2: ='Financial Statement '!K49 -> 37630 | N2: =L2+M2 -> 369328.87 | O2: =N2+K2 -> 1407334.9 | P2: ='Financial Statement '!K81 -> 439842.56 | Q2: ='Financial Statement '!K67 -> 967492.31 | R2: =P2+Q2 -> 1407334.9 | S2: =R2-O2 -> 0 | T2: ='Financial Statement '!K96 -> 2550000 | U2: ='Financial Statement '!K97 -> 300000 | V2: =P2-L2 -> 108143.69 | W2: ='Financial Statement '!K189 -> 100558 | X2: ='Financial Statement '!K185 -> 160000 | Y2: ='Financial Statement '!K203 -> 205349.35
A3: 2026 | B3: ='Financial Statement '!L8 -> 2071120.2 | C3: ='Financial Statement '!L18 -> 1721901.8 | D3: =B3-C3 -> 349218.35 | E3: ='Financial Statement '!L22 -> 67322.24 | F3: =D3-E3 -> 281896.11 | G3: ='Financial Statement '!L26 -> 1936 | H3: =F3-G3 -> 279960.11 | I3: ='Financial Statement '!L32 -> 69990.028 | J3: =H3-I3 -> 209970.08 | K3: ='Financial Statement '!L41 -> 1250517.1 | L3: ='Financial Statement '!L55 -> 388646.86 | M3: ='Financial Statement '!L49 -> 37630 | N3: =L3+M3 -> 426276.86 | O3: =N3+K3 -> 1676793.9 | P3: ='Financial Statement '!L81 -> 668388.19 | Q3: ='Financial Statement '!L67 -> 1008405.8 | R3: =P3+Q3 -> 1676793.9 | S3: =R3-O3 -> 0 | T3: ='Financial Statement '!L96 -> 2850000 | U3: =T3-T2 -> 300000 | V3: =P3-L3 -> 279741.32 | W3: ='Financial Statement '!L189 -> 108235.69 | X3: ='Financial Statement '!L185 -> 160000 | Y3: ='Financial Statement '!L203 -> 193140.71
A4: 2027 | B4: ='Financial Statement '!M8 -> 2424139.8 | C4: ='Financial Statement '!M18 -> 2018259.5 | D4: =B4-C4 -> 405880.34 | E4: ='Financial Statement '!M22 -> 74408.791 | F4: =D4-E4 -> 331471.55 | G4: ='Financial Statement '!M26 -> 1936 | H4: =F4-G4 -> 329535.55 | I4: ='Financial Statement '!M32 -> 82383.887 | J4: =H4-I4 -> 247151.66 | K4: ='Financial Statement '!M41 -> 1500209.7 | L4: ='Financial Statement '!M55 -> 455537.13 | M4: ='Financial Statement '!M49 -> 37630 | N4: =L4+M4 -> 493167.13 | O4: =N4+K4 -> 1993376.9 | P4: ='Financial Statement '!M81 -> 944057.67 | Q4: ='Financial Statement '!M67 -> 1049319.2 | R4: =P4+Q4 -> 1993376.9 | S4: =R4-O4 -> 0 | T4: ='Financial Statement '!M96 -> 3150000 | U4: =T4-T3 -> 300000 | V4: =P4-L4 -> 488520.54 | W4: ='Financial Statement '!M189 -> 115322.24 | X4: ='Financial Statement '!M185 -> 160000 | Y4: ='Financial Statement '!M203 -> 234083.39
A5: 2028 | B5: ='Financial Statement '!N8 -> 2838896 | C5: ='Financial Statement '!N18 -> 2366444.6 | D5: =B5-C5 -> 472451.45 | E5: ='Financial Statement '!N22 -> 81495.343 | F5: =D5-E5 -> 390956.11 | G5: ='Financial Statement '!N26 -> 1936 | H5: =F5-G5 -> 389020.11 | I5: ='Financial Statement '!N32 -> 97255.027 | J5: =H5-I5 -> 291765.08 | K5: ='Financial Statement '!N41 -> 1794515.8 | L5: ='Financial Statement '!N55 -> 534125.26 | M5: ='Financial Statement '!N49 -> 37630 | N5: =L5+M5 -> 571755.26 | O5: =N5+K5 -> 2366271.1 | P5: ='Financial Statement '!N81 -> 1276038.4 | Q5: ='Financial Statement '!N67 -> 1090232.7 | R5: =P5+Q5 -> 2366271.1 | S5: =R5-O5 -> 0 | T5: ='Financial Statement '!N96 -> 3450000 | U5: =T5-T4 -> 300000 | V5: =P5-L5 -> 741913.17 | W5: ='Financial Statement '!N189 -> 122408.79 | X5: ='Financial Statement '!N185 -> 160000 | Y5: ='Financial Statement '!N203 -> 283122.04
A6: 2029 | B6: ='Financial Statement '!O8 -> 3326302.3 | C6: ='Financial Statement '!O18 -> 2775618.9 | D6: =B6-C6 -> 550683.38 | E6: ='Financial Statement '!O22 -> 88581.894 | F6: =D6-E6 -> 462101.48 | G6: ='Financial Statement '!O26 -> 1936 | H6: =F6-G6 -> 460165.48 | I6: ='Financial Statement '!O32 -> 115041.37 | J6: =H6-I6 -> 345124.11 | K6: ='Financial Statement '!O41 -> 2142180.9 | L6: ='Financial Statement '!O55 -> 626479.14 | M6: ='Financial Statement '!O49 -> 37630 | N6: =L6+M6 -> 664109.14 | O6: =N6+K6 -> 2806290.1 | P6: ='Financial Statement '!O81 -> 1675144 | Q6: ='Financial Statement '!O67 -> 1131146.1 | R6: =P6+Q6 -> 2806290.1 | S6: =R6-O6 -> 0 | T6: ='Financial Statement '!O96 -> 3750000 | U6: =T6-T5 -> 300000 | V6: =P6-L6 -> 1048664.8 | W6: ='Financial Statement '!O189 -> 129495.34 | X6: ='Financial Statement '!O185 -> 160000 | Y6: ='Financial Statement '!O203 -> 341688.58
A7: 2030 | B7: ='Financial Statement '!P8 -> 3899215.2 | C7: ='Financial Statement '!P18 -> 3256575.5 | D7: =B7-C7 -> 642639.69 | E7: ='Financial Statement '!P22 -> 95668.446 | F7: =D7-E7 -> 546971.24 | G7: ='Financial Statement '!P26 -> 1936 | H7: =F7-G7 -> 545035.24 | I7: ='Financial Statement '!P32 -> 136258.81 | J7: =H7-I7 -> 408776.43 | K7: ='Financial Statement '!P41 -> 2553498.4 | L7: ='Financial Statement '!P55 -> 735034.85 | M7: ='Financial Statement '!P49 -> 37630 | N7: =L7+M7 -> 772664.85 | O7: =N7+K7 -> 3326163.2 | P7: ='Financial Statement '!P81 -> 2154103.7 | Q7: ='Financial Statement '!P67 -> 1172059.6 | R7: =P7+Q7 -> 3326163.2 | S7: =R7-O7 -> 0 | T7: ='Financial Statement '!P96 -> 4050000 | U7: =T7-T6 -> 300000 | V7: =P7-L7 -> 1419068.8 | W7: ='Financial Statement '!P189 -> 136581.89 | X7: ='Financial Statement '!P185 -> 160000 | Y7: ='Financial Statement '!P203 -> 411469.95
A15: Year
A16: 2025
A17: 2026
A18: 2027
A19: 2028
A20: 2029
A21: 2030
